

Error at 2024-01-17 00:11:55:
Traceback (most recent call last):
  File "C:\Users\kieran\Documents\Development\AbuseIPDB-Lookup\update_db.py", line 274, in main
    print_progress(i, total_ips, prefix="Progress:", suffix="Complete", length=50)
                   ^
UnboundLocalError: cannot access local variable 'i' where it is not associated with a value


Error at 2024-01-17 00:12:48:
Traceback (most recent call last):
  File "C:\Users\kieran\Documents\Development\AbuseIPDB-Lookup\update_db.py", line 279, in main
    print_progress(i, total_ips, progress_bar_lookup, prefix="Progress:", suffix="Complete", length=50)
                   ^
UnboundLocalError: cannot access local variable 'i' where it is not associated with a value


Error at 2024-01-17 00:14:28:
Traceback (most recent call last):
  File "C:\Users\kieran\Documents\Development\AbuseIPDB-Lookup\update_db.py", line 273, in main
    print_progress(i, total_ips, prefix="Progress:", suffix="Complete", length=50)
                   ^
UnboundLocalError: cannot access local variable 'i' where it is not associated with a value
